Workbook

Sheet raw sheet
B2: Sr. No. | C2: Product ID | D2: Prdocut Name | E2: Category | F2: System_Stock_Qty | G2: Physical_Stock_Qty | H2: Unit_Cost | J2: Electronics | K2: Unit Price | L2: Furniture | M2: Unit Price | N2: Stationery | O2: Unit Price | P2: Hardware | Q2: Unit Price | R2: Accessories | S2: Unit Price | T2: Networking | U2: Unit Price | W2: Electronics | X2: fridge, cooler, washing maching, Iphone, Tabs, smartwatch, Apple Watch, Car Play, Dryer, Cameras, Go pro, toster, Microwave, AC set
B3: 1 | C3: P001 | D3: Book Shelves | E3: Furniture | F3: 36 | G3: 133 | H3: 3000 | J3: fridge | K3: 20000 | L3: Bed | M3: 15000 | N3: Books | O3: 50 | P3: Hammer | Q3: 200 | R3: Data Cable | S3: 100 | T3: Router | U3: 5000 | W3: Furniture | X3: Bed, table, Dressing table, Chairs, Dinning table, Study Table, Doors, Book Shelves
B4: 2 | C4: P002 | D4: Car Play | E4: Electronics | F4: 192 | G4: 164 | H4: 15000 | J4: cooler | K4: 15000 | L4: table | M4: 8000 | N4: Pens | O4: 100 | P4: Screwdriver Set | Q4: 100 | R4: Iphone Charger | S4: 4500 | T4: Switch | U4: 200 | W4: Stationery | X4: Books, Pens, Pencils, Eraser, maps, Cardboard, Whitener, Scratch Book, Colors, Geomatery box, Scales, Compas, Sticky Notes
B5: 3 | C5: P003 | D5: Pen Drive | E5: Accessories | F5: 191 | G5: 36 | H5: 200 | J5: washing maching | K5: 20000 | L5: Dressing table | M5: 10000 | N5: Pencils | O5: 100 | P5: Wrench | Q5: 500 | R5: Smartphone | S5: 15000 | T5: Network Cable (Ethernet) | U5: 5000 | W5: Hardware | X5: Hammer, Screwdriver Set, Wrench, Drill Machine, Pilers, Measuring Tape, Chain Saw Blade, Screws
B6: 4 | C6: P004 | D6: Books | E6: Stationery | F6: 91 | G6: 91 | H6: 50 | J6: Iphone | K6: 150000 | L6: Chairs | M6: 5000 | N6: Eraser | O6: 100 | P6: Drill Machine | Q6: 3000 | R6: Headphone | S6: 200 | T6: AccessPoint (Wi-Fi AP) | U6: 2500 | W6: Accessories | X6: Data Cable, Iphone Charger, Smartphone, Headphone, Ear Buds, Phone case, USB, Pen Drive, Wireless Charger, Phone Mount, Screen Guard, Smartwatch Case, Phone Mount, Bike Mount, Tablet Cover, smartphone Skins
B7: 5 | C7: P005 | D7: Rack Mount Kit | E7: Networking | F7: 62 | G7: 62 | H7: 5000 | J7: Tabs | K7: 30000 | L7: Dinning table | M7: 12000 | N7: maps | O7: 500 | P7: Pilers | Q7: 500 | R7: Ear Buds | S7: 800 | T7: Firewall Appliance | U7: 1000 | W7: Networking | X7: Router, Switch, Network Cable (Ethernet), AccessPoint (Wi-Fi AP), Firewall Appliance, Network Interface Card (NIC), Path Pane, Modem, SFP Module (Fiber Transceiver), Cable Tester, Rack Mount Kit
B8: 6 | C8: P006 | D8: Cardboard | E8: Stationery | F8: 98 | G8: 98 | H8: 50 | J8: smartwatch | K8: 6000 | L8: Study Table | M8: 5000 | N8: Cardboard | O8: 50 | P8: Measuring Tape | Q8: 200 | R8: Phone case | S8: 100 | T8: Network Interface Card (NIC) | U8: 2000
B9: 7 | C9: P007 | D9: Network Interface Card (NIC) | E9: Networking | F9: 184 | G9: 184 | H9: 2000 | J9: Apple Watch | K9: 30000 | L9: Doors | M9: 2000 | N9: Whitener | O9: 20 | P9: Chain Saw Blade | Q9: 1500 | R9: USB | S9: 100 | T9: Path Pane | U9: 3000
B10: 8 | C10: P008 | D10: table | E10: Furniture | F10: 79 | G10: 79 | H10: 8000 | J10: Car Play | K10: 15000 | L10: Book Shelves | M10: 3000 | N10: Scratch Book | O10: 30 | P10: Screws | Q10: 500 | R10: Pen Drive | S10: 200 | T10: Modem | U10: 2000
B11: 9 | C11: P009 | D11: Network Cable (Ethernet) | E11: Networking | F11: 68 | G11: 68 | H11: 5000 | J11: Dryer | K11: 3000 | N11: Colors | O11: 50 | R11: Wireless Charger | S11: 1500 | T11: SFP Module (Fiber Transceiver) | U11: 1500
B12: 10 | C12: P010 | D12: Apple Watch | E12: Electronics | F12: 161 | G12: 161 | H12: 30000 | J12: Cameras | K12: 70000 | N12: Geomatery box | O12: 100 | R12: Phone Mount | S12: 200 | T12: Cable Tester | U12: 4500
B13: 11 | C13: P011 | D13: Pilers | E13: Hardware | F13: 34 | G13: 34 | H13: 500 | J13: Go pro | K13: 40000 | N13: Scales | O13: 10 | R13: Screen Guard | S13: 50 | T13: Rack Mount Kit | U13: 5000
B14: 12 | C14: P012 | D14: Drill Machine | E14: Hardware | F14: 43 | G14: 43 | H14: 3000 | J14: toster | K14: 2000 | N14: Compas | O14: 30 | R14: Smartwatch Case | S14: 100
B15: 13 | C15: P013 | D15: Chain Saw Blade | E15: Hardware | F15: 79 | G15: 79 | H15: 1500 | J15: Microwave | K15: 4000 | N15: Sticky Notes | O15: 50 | R15: Phone Mount | S15: 200
B16: 14 | C16: P014 | D16: Scratch Book | E16: Stationery | F16: 195 | G16: 195 | H16: 30 | J16: AC set | K16: 50000 | R16: Bike Mount | S16: 500
B17: 15 | C17: P015 | D17: Books | E17: Stationery | F17: 184 | G17: 184 | H17: 50
B18: 16 | C18: P016 | D18: table | E18: Furniture | F18: 46 | G18: 46 | H18: 8000
B19: 17 | C19: P017 | D19: smartwatch | E19: Electronics | F19: 165 | G19: 165 | H19: 6000 | J19: Status
B20: 18 | C20: P018 | D20: Bed | E20: Furniture | F20: 40 | G20: 40 | H20: 15000 | J20: Excess
B21: 19 | C21: P019 | D21: Phone case | E21: Accessories | F21: 96 | G21: 96 | H21: 100 | J21: Shortage
B22: 20 | C22: P020 | D22: Compas | E22: Stationery | F22: 159 | G22: 159 | H22: 30 | J22: Matched
B23: 21 | C23: P021 | D23: fridge | E23: Electronics | F23: 159 | G23: 159 | H23: 20000
B24: 22 | C24: P022 | D24: Chairs | E24: Furniture | F24: 52 | G24: 52 | H24: 5000
B25: 23 | C25: P023 | D25: Study Table | E25: Furniture | F25: 178 | G25: 178 | H25: 5000
B26: 24 | C26: P024 | D26: Screwdriver Set | E26: Hardware | F26: 93 | G26: 93 | H26: 100
B27: 25 | C27: P025 | D27: Pilers | E27: Hardware | F27: 31 | G27: 31 | H27: 500
B28: 26 | C28: P026 | D28: Headphone | E28: Accessories | F28: 99 | G28: 99 | H28: 200
B29: 27 | C29: P027 | D29: Tablet Cover | E29: Accessories | F29: 82 | G29: 82 | H29: 2000
B30: 28 | C30: P028 | D30: Drill Machine | E30: Hardware | F30: 91 | G30: 91 | H30: 3000
B31: 29 | C31: P029 | D31: Hammer | E31: Hardware | F31: 165 | G31: 165 | H31: 200
B32: 30 | C32: P030 | D32: Chairs | E32: Furniture | F32: 76 | G32: 76 | H32: 5000
B33: 31 | C33: P031 | D33: Chairs | E33: Furniture | F33: 86 | G33: 86 | H33: 5000
B34: 32 | C34: P032 | D34: Cardboard | E34: Stationery | F34: 197 | G34: 197 | H34: 50
... B1002: 1000 | C1002: P1000 | D1002: Drill Machine | E1002: Hardware | F1002: 53 | G1002: 53 | H1002: 3000

Sheet calcu sheet
A1: Product ID | B1: Prdocut Name | C1: Category | D1: Unit_price
A2: P001 | B2: Book Shelves | C2: Furniture | D2: =_xlfn.XLOOKUP(B2, $H$11:$H$24, $I$11:$I$24, _xlfn.XLOOKUP(B2, $J$11:$J$24, $K$11:$K$24,_xlfn.XLOOKUP(B2, $L$11:$L$23,$M$11:$M$23,_xlfn.XLOOKUP(B2, $N$11:$N$18,$O$11:$O$18,_xlfn.XLOOKUP(B2, $P$11:$P$26,$Q$11:$Q$26,_xlfn.XLOOKUP(B2, $R$11:$R$21,$S$11:$S$21,0)))))) -> 3000
A3: P002 | B3: Car Play | C3: Electronics | D3: =_xlfn.XLOOKUP(B3, $H$11:$H$24, $I$11:$I$24, _xlfn.XLOOKUP(B3, $J$11:$J$24, $K$11:$K$24,_xlfn.XLOOKUP(B3, $L$11:$L$23,$M$11:$M$23,_xlfn.XLOOKUP(B3, $N$11:$N$18,$O$11:$O$18,_xlfn.XLOOKUP(B3, $P$11:$P$26,$Q$11:$Q$26,_xlfn.XLOOKUP(B3, $R$11:$R$21,$S$11:$S$21,0)))))) -> 15000 | G3: Electronics | H3: fridge | I3: cooler | J3: washing maching | K3: Iphone | L3: Tabs | M3: smartwatch | N3: Apple Watch | O3: Car Play | P3: Dryer | Q3: Cameras | R3: Go pro | S3: toster | T3: Microwave | U3: AC set
A4: P003 | B4: Pen Drive | C4: Accessories | D4: =_xlfn.XLOOKUP(B4, $H$11:$H$24, $I$11:$I$24, _xlfn.XLOOKUP(B4, $J$11:$J$24, $K$11:$K$24,_xlfn.XLOOKUP(B4, $L$11:$L$23,$M$11:$M$23,_xlfn.XLOOKUP(B4, $N$11:$N$18,$O$11:$O$18,_xlfn.XLOOKUP(B4, $P$11:$P$26,$Q$11:$Q$26,_xlfn.XLOOKUP(B4, $R$11:$R$21,$S$11:$S$21,0)))))) -> 200 | G4: Furniture | H4: Bed | I4: table | J4: Dressing table | K4: Chairs | L4: Dinning table | M4: Study Table | N4: Doors | O4: Book Shelves
A5: P004 | B5: Books | C5: Stationery | D5: =_xlfn.XLOOKUP(B5, $H$11:$H$24, $I$11:$I$24, _xlfn.XLOOKUP(B5, $J$11:$J$24, $K$11:$K$24,_xlfn.XLOOKUP(B5, $L$11:$L$23,$M$11:$M$23,_xlfn.XLOOKUP(B5, $N$11:$N$18,$O$11:$O$18,_xlfn.XLOOKUP(B5, $P$11:$P$26,$Q$11:$Q$26,_xlfn.XLOOKUP(B5, $R$11:$R$21,$S$11:$S$21,0)))))) -> 50 | G5: Stationery | H5: Books | I5: Pens | J5: Pencils | K5: Eraser | L5: maps | M5: Cardboard | N5: Whitener | O5: Scratch Book | P5: Colors | Q5: Geomatery box | R5: Scales | S5: Compas | T5: Sticky Notes
A6: P005 | B6: Rack Mount Kit | C6: Networking | D6: =_xlfn.XLOOKUP(B6, $H$11:$H$24, $I$11:$I$24, _xlfn.XLOOKUP(B6, $J$11:$J$24, $K$11:$K$24,_xlfn.XLOOKUP(B6, $L$11:$L$23,$M$11:$M$23,_xlfn.XLOOKUP(B6, $N$11:$N$18,$O$11:$O$18,_xlfn.XLOOKUP(B6, $P$11:$P$26,$Q$11:$Q$26,_xlfn.XLOOKUP(B6, $R$11:$R$21,$S$11:$S$21,0)))))) -> 5000 | G6: Hardware | H6: Hammer | I6: Screwdriver Set | J6: Wrench | K6: Drill Machine | L6: Pilers | M6: Measuring Tape | N6: Chain Saw Blade | O6: Screws
A7: P006 | B7: Cardboard | C7: Stationery | D7: =_xlfn.XLOOKUP(B7, $H$11:$H$24, $I$11:$I$24, _xlfn.XLOOKUP(B7, $J$11:$J$24, $K$11:$K$24,_xlfn.XLOOKUP(B7, $L$11:$L$23,$M$11:$M$23,_xlfn.XLOOKUP(B7, $N$11:$N$18,$O$11:$O$18,_xlfn.XLOOKUP(B7, $P$11:$P$26,$Q$11:$Q$26,_xlfn.XLOOKUP(B7, $R$11:$R$21,$S$11:$S$21,0)))))) -> 50 | G7: Accessories | H7: Data Cable | I7: Iphone Charger | J7: Smartphone | K7: Headphone | L7: Ear Buds | M7: Phone case | N7: USB | O7: Pen Drive | P7: Wireless Charger | Q7: Phone Mount | R7: Screen Guard | S7: Smartwatch Case | T7: Phone Mount | U7: Bike Mount | V7: Tablet Cover | W7: smartphone Skins
A8: P007 | B8: Network Interface Card (NIC) | C8: Networking | D8: =_xlfn.XLOOKUP(B8, $H$11:$H$24, $I$11:$I$24, _xlfn.XLOOKUP(B8, $J$11:$J$24, $K$11:$K$24,_xlfn.XLOOKUP(B8, $L$11:$L$23,$M$11:$M$23,_xlfn.XLOOKUP(B8, $N$11:$N$18,$O$11:$O$18,_xlfn.XLOOKUP(B8, $P$11:$P$26,$Q$11:$Q$26,_xlfn.XLOOKUP(B8, $R$11:$R$21,$S$11:$S$21,0)))))) -> 2000 | G8: Networking | H8: Router | I8: Switch | J8: Network Cable (Ethernet) | K8: AccessPoint (Wi-Fi AP) | L8: Firewall Appliance | M8: Network Interface Card (NIC) | N8: Path Pane | O8: Modem | P8: SFP Module (Fiber Transceiver) | Q8: Cable Tester | R8: Rack Mount Kit
A9: P008 | B9: table | C9: Furniture | D9: =_xlfn.XLOOKUP(B9, $H$11:$H$24, $I$11:$I$24, _xlfn.XLOOKUP(B9, $J$11:$J$24, $K$11:$K$24,_xlfn.XLOOKUP(B9, $L$11:$L$23,$M$11:$M$23,_xlfn.XLOOKUP(B9, $N$11:$N$18,$O$11:$O$18,_xlfn.XLOOKUP(B9, $P$11:$P$26,$Q$11:$Q$26,_xlfn.XLOOKUP(B9, $R$11:$R$21,$S$11:$S$21,0)))))) -> 8000
A10: P009 | B10: Network Cable (Ethernet) | C10: Networking | D10: =_xlfn.XLOOKUP(B10, $H$11:$H$24, $I$11:$I$24, _xlfn.XLOOKUP(B10, $J$11:$J$24, $K$11:$K$24,_xlfn.XLOOKUP(B10, $L$11:$L$23,$M$11:$M$23,_xlfn.XLOOKUP(B10, $N$11:$N$18,$O$11:$O$18,_xlfn.XLOOKUP(B10, $P$11:$P$26,$Q$11:$Q$26,_xlfn.XLOOKUP(B10, $R$11:$R$21,$S$11:$S$21,0)))))) -> 5000 | H10: Electronics | I10: Unit Price | J10: Furniture | K10: Unit Price | L10: Stationery | M10: Unit Price | N10: Hardware | O10: Unit Price | P10: Accessories | Q10: Unit Price | R10: Networking | S10: Unit Price
A11: P010 | B11: Apple Watch | C11: Electronics | D11: =_xlfn.XLOOKUP(B11, $H$11:$H$24, $I$11:$I$24, _xlfn.XLOOKUP(B11, $J$11:$J$24, $K$11:$K$24,_xlfn.XLOOKUP(B11, $L$11:$L$23,$M$11:$M$23,_xlfn.XLOOKUP(B11, $N$11:$N$18,$O$11:$O$18,_xlfn.XLOOKUP(B11, $P$11:$P$26,$Q$11:$Q$26,_xlfn.XLOOKUP(B11, $R$11:$R$21,$S$11:$S$21,0)))))) -> 30000 | H11: fridge | I11: 20000 | J11: Bed | K11: 15000 | L11: Books | M11: 50 | N11: Hammer | O11: 200 | P11: Data Cable | Q11: 100 | R11: Router | S11: 5000
A12: P011 | B12: Pilers | C12: Hardware | D12: =_xlfn.XLOOKUP(B12, $H$11:$H$24, $I$11:$I$24, _xlfn.XLOOKUP(B12, $J$11:$J$24, $K$11:$K$24,_xlfn.XLOOKUP(B12, $L$11:$L$23,$M$11:$M$23,_xlfn.XLOOKUP(B12, $N$11:$N$18,$O$11:$O$18,_xlfn.XLOOKUP(B12, $P$11:$P$26,$Q$11:$Q$26,_xlfn.XLOOKUP(B12, $R$11:$R$21,$S$11:$S$21,0)))))) -> 500 | H12: cooler | I12: 15000 | J12: table | K12: 8000 | L12: Pens | M12: 100 | N12: Screwdriver Set | O12: 100 | P12: Iphone Charger | Q12: 4500 | R12: Switch | S12: 200 | U12: Formula to get unit price :-XLOOKUP(B2, $H$11:$H$24, $I$11:$I$24, XLOOKUP(B2, $J$11:$J$24, $K$11:$K$24,XLOOKUP(B2, $L$11:$L$23,$M$11:$M$23,XLOOKUP(B2, $N$11:$N$18,$O$11:$O$18,XLOOKUP(B2, $P$11:$P$26,$Q$11:$Q$26,XLOOKUP(B2, $R$11:$R$21,$S$11:$S$21,0))))))
A13: P012 | B13: Drill Machine | C13: Hardware | D13: =_xlfn.XLOOKUP(B13, $H$11:$H$24, $I$11:$I$24, _xlfn.XLOOKUP(B13, $J$11:$J$24, $K$11:$K$24,_xlfn.XLOOKUP(B13, $L$11:$L$23,$M$11:$M$23,_xlfn.XLOOKUP(B13, $N$11:$N$18,$O$11:$O$18,_xlfn.XLOOKUP(B13, $P$11:$P$26,$Q$11:$Q$26,_xlfn.XLOOKUP(B13, $R$11:$R$21,$S$11:$S$21,0)))))) -> 3000 | H13: washing maching | I13: 20000 | J13: Dressing table | K13: 10000 | L13: Pencils | M13: 100 | N13: Wrench | O13: 500 | P13: Smartphone | Q13: 15000 | R13: Network Cable (Ethernet) | S13: 5000
A14: P013 | B14: Chain Saw Blade | C14: Hardware | D14: =_xlfn.XLOOKUP(B14, $H$11:$H$24, $I$11:$I$24, _xlfn.XLOOKUP(B14, $J$11:$J$24, $K$11:$K$24,_xlfn.XLOOKUP(B14, $L$11:$L$23,$M$11:$M$23,_xlfn.XLOOKUP(B14, $N$11:$N$18,$O$11:$O$18,_xlfn.XLOOKUP(B14, $P$11:$P$26,$Q$11:$Q$26,_xlfn.XLOOKUP(B14, $R$11:$R$21,$S$11:$S$21,0)))))) -> 1500 | H14: Iphone | I14: 150000 | J14: Chairs | K14: 5000 | L14: Eraser | M14: 100 | N14: Drill Machine | O14: 3000 | P14: Headphone | Q14: 200 | R14: AccessPoint (Wi-Fi AP) | S14: 2500
A15: P014 | B15: Scratch Book | C15: Stationery | D15: =_xlfn.XLOOKUP(B15, $H$11:$H$24, $I$11:$I$24, _xlfn.XLOOKUP(B15, $J$11:$J$24, $K$11:$K$24,_xlfn.XLOOKUP(B15, $L$11:$L$23,$M$11:$M$23,_xlfn.XLOOKUP(B15, $N$11:$N$18,$O$11:$O$18,_xlfn.XLOOKUP(B15, $P$11:$P$26,$Q$11:$Q$26,_xlfn.XLOOKUP(B15, $R$11:$R$21,$S$11:$S$21,0)))))) -> 30 | H15: Tabs | I15: 30000 | J15: Dinning table | K15: 12000 | L15: maps | M15: 500 | N15: Pilers | O15: 500 | P15: Ear Buds | Q15: 800 | R15: Firewall Appliance | S15: 1000
A16: P015 | B16: Books | C16: Stationery | D16: =_xlfn.XLOOKUP(B16, $H$11:$H$24, $I$11:$I$24, _xlfn.XLOOKUP(B16, $J$11:$J$24, $K$11:$K$24,_xlfn.XLOOKUP(B16, $L$11:$L$23,$M$11:$M$23,_xlfn.XLOOKUP(B16, $N$11:$N$18,$O$11:$O$18,_xlfn.XLOOKUP(B16, $P$11:$P$26,$Q$11:$Q$26,_xlfn.XLOOKUP(B16, $R$11:$R$21,$S$11:$S$21,0)))))) -> 50 | H16: smartwatch | I16: 6000 | J16: Study Table | K16: 5000 | L16: Cardboard | M16: 50 | N16: Measuring Tape | O16: 200 | P16: Phone case | Q16: 100 | R16: Network Interface Card (NIC) | S16: 2000
A17: P016 | B17: table | C17: Furniture | D17: =_xlfn.XLOOKUP(B17, $H$11:$H$24, $I$11:$I$24, _xlfn.XLOOKUP(B17, $J$11:$J$24, $K$11:$K$24,_xlfn.XLOOKUP(B17, $L$11:$L$23,$M$11:$M$23,_xlfn.XLOOKUP(B17, $N$11:$N$18,$O$11:$O$18,_xlfn.XLOOKUP(B17, $P$11:$P$26,$Q$11:$Q$26,_xlfn.XLOOKUP(B17, $R$11:$R$21,$S$11:$S$21,0)))))) -> 8000 | H17: Apple Watch | I17: 30000 | J17: Doors | K17: 2000 | L17: Whitener | M17: 20 | N17: Chain Saw Blade | O17: 1500 | P17: USB | Q17: 100 | R17: Path Pane | S17: 3000
A18: P017 | B18: smartwatch | C18: Electronics | D18: =_xlfn.XLOOKUP(B18, $H$11:$H$24, $I$11:$I$24, _xlfn.XLOOKUP(B18, $J$11:$J$24, $K$11:$K$24,_xlfn.XLOOKUP(B18, $L$11:$L$23,$M$11:$M$23,_xlfn.XLOOKUP(B18, $N$11:$N$18,$O$11:$O$18,_xlfn.XLOOKUP(B18, $P$11:$P$26,$Q$11:$Q$26,_xlfn.XLOOKUP(B18, $R$11:$R$21,$S$11:$S$21,0)))))) -> 6000 | H18: Car Play | I18: 15000 | J18: Book Shelves | K18: 3000 | L18: Scratch Book | M18: 30 | N18: Screws | O18: 500 | P18: Pen Drive | Q18: 200 | R18: Modem | S18: 2000
A19: P018 | B19: Bed | C19: Furniture | D19: =_xlfn.XLOOKUP(B19, $H$11:$H$24, $I$11:$I$24, _xlfn.XLOOKUP(B19, $J$11:$J$24, $K$11:$K$24,_xlfn.XLOOKUP(B19, $L$11:$L$23,$M$11:$M$23,_xlfn.XLOOKUP(B19, $N$11:$N$18,$O$11:$O$18,_xlfn.XLOOKUP(B19, $P$11:$P$26,$Q$11:$Q$26,_xlfn.XLOOKUP(B19, $R$11:$R$21,$S$11:$S$21,0)))))) -> 15000 | H19: Dryer | I19: 3000 | L19: Colors | M19: 50 | P19: Wireless Charger | Q19: 1500 | R19: SFP Module (Fiber Transceiver) | S19: 1500
A20: P019 | B20: Phone case | C20: Accessories | D20: =_xlfn.XLOOKUP(B20, $H$11:$H$24, $I$11:$I$24, _xlfn.XLOOKUP(B20, $J$11:$J$24, $K$11:$K$24,_xlfn.XLOOKUP(B20, $L$11:$L$23,$M$11:$M$23,_xlfn.XLOOKUP(B20, $N$11:$N$18,$O$11:$O$18,_xlfn.XLOOKUP(B20, $P$11:$P$26,$Q$11:$Q$26,_xlfn.XLOOKUP(B20, $R$11:$R$21,$S$11:$S$21,0)))))) -> 100 | H20: Cameras | I20: 70000 | L20: Geomatery box | M20: 100 | P20: Phone Mount | Q20: 200 | R20: Cable Tester | S20: 4500
A21: P020 | B21: Compas | C21: Stationery | D21: =_xlfn.XLOOKUP(B21, $H$11:$H$24, $I$11:$I$24, _xlfn.XLOOKUP(B21, $J$11:$J$24, $K$11:$K$24,_xlfn.XLOOKUP(B21, $L$11:$L$23,$M$11:$M$23,_xlfn.XLOOKUP(B21, $N$11:$N$18,$O$11:$O$18,_xlfn.XLOOKUP(B21, $P$11:$P$26,$Q$11:$Q$26,_xlfn.XLOOKUP(B21, $R$11:$R$21,$S$11:$S$21,0)))))) -> 30 | H21: Go pro | I21: 40000 | L21: Scales | M21: 10 | P21: Screen Guard | Q21: 50 | R21: Rack Mount Kit | S21: 5000
A22: P021 | B22: fridge | C22: Electronics | D22: =_xlfn.XLOOKUP(B22, $H$11:$H$24, $I$11:$I$24, _xlfn.XLOOKUP(B22, $J$11:$J$24, $K$11:$K$24,_xlfn.XLOOKUP(B22, $L$11:$L$23,$M$11:$M$23,_xlfn.XLOOKUP(B22, $N$11:$N$18,$O$11:$O$18,_xlfn.XLOOKUP(B22, $P$11:$P$26,$Q$11:$Q$26,_xlfn.XLOOKUP(B22, $R$11:$R$21,$S$11:$S$21,0)))))) -> 20000 | H22: toster | I22: 2000 | L22: Compas | M22: 30 | P22: Smartwatch Case | Q22: 100
A23: P022 | B23: Chairs | C23: Furniture | D23: =_xlfn.XLOOKUP(B23, $H$11:$H$24, $I$11:$I$24, _xlfn.XLOOKUP(B23, $J$11:$J$24, $K$11:$K$24,_xlfn.XLOOKUP(B23, $L$11:$L$23,$M$11:$M$23,_xlfn.XLOOKUP(B23, $N$11:$N$18,$O$11:$O$18,_xlfn.XLOOKUP(B23, $P$11:$P$26,$Q$11:$Q$26,_xlfn.XLOOKUP(B23, $R$11:$R$21,$S$11:$S$21,0)))))) -> 5000 | H23: Microwave | I23: 4000 | L23: Sticky Notes | M23: 50 | P23: Phone Mount | Q23: 200
A24: P023 | B24: Study Table | C24: Furniture | D24: =_xlfn.XLOOKUP(B24, $H$11:$H$24, $I$11:$I$24, _xlfn.XLOOKUP(B24, $J$11:$J$24, $K$11:$K$24,_xlfn.XLOOKUP(B24, $L$11:$L$23,$M$11:$M$23,_xlfn.XLOOKUP(B24, $N$11:$N$18,$O$11:$O$18,_xlfn.XLOOKUP(B24, $P$11:$P$26,$Q$11:$Q$26,_xlfn.XLOOKUP(B24, $R$11:$R$21,$S$11:$S$21,0)))))) -> 5000 | H24: AC set | I24: 50000 | P24: Bike Mount | Q24: 500
A25: P024 | B25: Screwdriver Set | C25: Hardware | D25: =_xlfn.XLOOKUP(B25, $H$11:$H$24, $I$11:$I$24, _xlfn.XLOOKUP(B25, $J$11:$J$24, $K$11:$K$24,_xlfn.XLOOKUP(B25, $L$11:$L$23,$M$11:$M$23,_xlfn.XLOOKUP(B25, $N$11:$N$18,$O$11:$O$18,_xlfn.XLOOKUP(B25, $P$11:$P$26,$Q$11:$Q$26,_xlfn.XLOOKUP(B25, $R$11:$R$21,$S$11:$S$21,0)))))) -> 100 | P25: Tablet Cover | Q25: 2000
A26: P025 | B26: Pilers | C26: Hardware | D26: =_xlfn.XLOOKUP(B26, $H$11:$H$24, $I$11:$I$24, _xlfn.XLOOKUP(B26, $J$11:$J$24, $K$11:$K$24,_xlfn.XLOOKUP(B26, $L$11:$L$23,$M$11:$M$23,_xlfn.XLOOKUP(B26, $N$11:$N$18,$O$11:$O$18,_xlfn.XLOOKUP(B26, $P$11:$P$26,$Q$11:$Q$26,_xlfn.XLOOKUP(B26, $R$11:$R$21,$S$11:$S$21,0)))))) -> 500 | P26: smartphone Skins | Q26: 100
A27: P026 | B27: Headphone | C27: Accessories | D27: =_xlfn.XLOOKUP(B27, $H$11:$H$24, $I$11:$I$24, _xlfn.XLOOKUP(B27, $J$11:$J$24, $K$11:$K$24,_xlfn.XLOOKUP(B27, $L$11:$L$23,$M$11:$M$23,_xlfn.XLOOKUP(B27, $N$11:$N$18,$O$11:$O$18,_xlfn.XLOOKUP(B27, $P$11:$P$26,$Q$11:$Q$26,_xlfn.XLOOKUP(B27, $R$11:$R$21,$S$11:$S$21,0)))))) -> 200
A28: P027 | B28: Tablet Cover | C28: Accessories | D28: =_xlfn.XLOOKUP(B28, $H$11:$H$24, $I$11:$I$24, _xlfn.XLOOKUP(B28, $J$11:$J$24, $K$11:$K$24,_xlfn.XLOOKUP(B28, $L$11:$L$23,$M$11:$M$23,_xlfn.XLOOKUP(B28, $N$11:$N$18,$O$11:$O$18,_xlfn.XLOOKUP(B28, $P$11:$P$26,$Q$11:$Q$26,_xlfn.XLOOKUP(B28, $R$11:$R$21,$S$11:$S$21,0)))))) -> 2000
A29: P028 | B29: Drill Machine | C29: Hardware | D29: =_xlfn.XLOOKUP(B29, $H$11:$H$24, $I$11:$I$24, _xlfn.XLOOKUP(B29, $J$11:$J$24, $K$11:$K$24,_xlfn.XLOOKUP(B29, $L$11:$L$23,$M$11:$M$23,_xlfn.XLOOKUP(B29, $N$11:$N$18,$O$11:$O$18,_xlfn.XLOOKUP(B29, $P$11:$P$26,$Q$11:$Q$26,_xlfn.XLOOKUP(B29, $R$11:$R$21,$S$11:$S$21,0)))))) -> 3000
A30: P029 | B30: Hammer | C30: Hardware | D30: =_xlfn.XLOOKUP(B30, $H$11:$H$24, $I$11:$I$24, _xlfn.XLOOKUP(B30, $J$11:$J$24, $K$11:$K$24,_xlfn.XLOOKUP(B30, $L$11:$L$23,$M$11:$M$23,_xlfn.XLOOKUP(B30, $N$11:$N$18,$O$11:$O$18,_xlfn.XLOOKUP(B30, $P$11:$P$26,$Q$11:$Q$26,_xlfn.XLOOKUP(B30, $R$11:$R$21,$S$11:$S$21,0)))))) -> 200
A31: P030 | B31: Chairs | C31: Furniture | D31: =_xlfn.XLOOKUP(B31, $H$11:$H$24, $I$11:$I$24, _xlfn.XLOOKUP(B31, $J$11:$J$24, $K$11:$K$24,_xlfn.XLOOKUP(B31, $L$11:$L$23,$M$11:$M$23,_xlfn.XLOOKUP(B31, $N$11:$N$18,$O$11:$O$18,_xlfn.XLOOKUP(B31, $P$11:$P$26,$Q$11:$Q$26,_xlfn.XLOOKUP(B31, $R$11:$R$21,$S$11:$S$21,0)))))) -> 5000
A32: P031 | B32: Chairs | C32: Furniture | D32: =_xlfn.XLOOKUP(B32, $H$11:$H$24, $I$11:$I$24, _xlfn.XLOOKUP(B32, $J$11:$J$24, $K$11:$K$24,_xlfn.XLOOKUP(B32, $L$11:$L$23,$M$11:$M$23,_xlfn.XLOOKUP(B32, $N$11:$N$18,$O$11:$O$18,_xlfn.XLOOKUP(B32, $P$11:$P$26,$Q$11:$Q$26,_xlfn.XLOOKUP(B32, $R$11:$R$21,$S$11:$S$21,0)))))) -> 5000
A33: P032 | B33: Cardboard | C33: Stationery | D33: =_xlfn.XLOOKUP(B33, $H$11:$H$24, $I$11:$I$24, _xlfn.XLOOKUP(B33, $J$11:$J$24, $K$11:$K$24,_xlfn.XLOOKUP(B33, $L$11:$L$23,$M$11:$M$23,_xlfn.XLOOKUP(B33, $N$11:$N$18,$O$11:$O$18,_xlfn.XLOOKUP(B33, $P$11:$P$26,$Q$11:$Q$26,_xlfn.XLOOKUP(B33, $R$11:$R$21,$S$11:$S$21,0)))))) -> 50
A34: P033 | B34: maps | C34: Stationery | D34: =_xlfn.XLOOKUP(B34, $H$11:$H$24, $I$11:$I$24, _xlfn.XLOOKUP(B34, $J$11:$J$24, $K$11:$K$24,_xlfn.XLOOKUP(B34, $L$11:$L$23,$M$11:$M$23,_xlfn.XLOOKUP(B34, $N$11:$N$18,$O$11:$O$18,_xlfn.XLOOKUP(B34, $P$11:$P$26,$Q$11:$Q$26,_xlfn.XLOOKUP(B34, $R$11:$R$21,$S$11:$S$21,0)))))) -> 500
A35: P034 | B35: Iphone Charger | C35: Accessories | D35: =_xlfn.XLOOKUP(B35, $H$11:$H$24, $I$11:$I$24, _xlfn.XLOOKUP(B35, $J$11:$J$24, $K$11:$K$24,_xlfn.XLOOKUP(B35, $L$11:$L$23,$M$11:$M$23,_xlfn.XLOOKUP(B35, $N$11:$N$18,$O$11:$O$18,_xlfn.XLOOKUP(B35, $P$11:$P$26,$Q$11:$Q$26,_xlfn.XLOOKUP(B35, $R$11:$R$21,$S$11:$S$21,0)))))) -> 4500
A36: P035 | B36: Dryer | C36: Electronics | D36: =_xlfn.XLOOKUP(B36, $H$11:$H$24, $I$11:$I$24, _xlfn.XLOOKUP(B36, $J$11:$J$24, $K$11:$K$24,_xlfn.XLOOKUP(B36, $L$11:$L$23,$M$11:$M$23,_xlfn.XLOOKUP(B36, $N$11:$N$18,$O$11:$O$18,_xlfn.XLOOKUP(B36, $P$11:$P$26,$Q$11:$Q$26,_xlfn.XLOOKUP(B36, $R$11:$R$21,$S$11:$S$21,0)))))) -> 3000
A37: P036 | B37: Pilers | C37: Hardware | D37: =_xlfn.XLOOKUP(B37, $H$11:$H$24, $I$11:$I$24, _xlfn.XLOOKUP(B37, $J$11:$J$24, $K$11:$K$24,_xlfn.XLOOKUP(B37, $L$11:$L$23,$M$11:$M$23,_xlfn.XLOOKUP(B37, $N$11:$N$18,$O$11:$O$18,_xlfn.XLOOKUP(B37, $P$11:$P$26,$Q$11:$Q$26,_xlfn.XLOOKUP(B37, $R$11:$R$21,$S$11:$S$21,0)))))) -> 500
A38: P037 | B38: Firewall Appliance | C38: Networking | D38: =_xlfn.XLOOKUP(B38, $H$11:$H$24, $I$11:$I$24, _xlfn.XLOOKUP(B38, $J$11:$J$24, $K$11:$K$24,_xlfn.XLOOKUP(B38, $L$11:$L$23,$M$11:$M$23,_xlfn.XLOOKUP(B38, $N$11:$N$18,$O$11:$O$18,_xlfn.XLOOKUP(B38, $P$11:$P$26,$Q$11:$Q$26,_xlfn.XLOOKUP(B38, $R$11:$R$21,$S$11:$S$21,0)))))) -> 1000
... A1001: P1000 | B1001: Drill Machine | C1001: Hardware | D1001: =_xlfn.XLOOKUP(B1001, $H$11:$H$24, $I$11:$I$24, _xlfn.XLOOKUP(B1001, $J$11:$J$24, $K$11:$K$24,_xlfn.XLOOKUP(B1001, $L$11:$L$23,$M$11:$M$23,_xlfn.XLOOKUP(B1001, $N$11:$N$18,$O$11:$O$18,_xlfn.XLOOKUP(B1001, $P$11:$P$26,$Q$11:$Q$26,_xlfn.XLOOKUP(B1001, $R$11:$R$21,$S$11:$S$21,0)))))) -> 3000

Sheet main sheet
B2: Sr. No. | C2: Product ID | D2: Prdocut Name | E2: Category | F2: System_Stock_Qty | G2: Physical_Stock_Qty | H2: Unit_Cost | I2: Stock Difference | J2: Status | K2: Mismatch Qty | L2: Value Impact | M2: Total Product Value | N2: Severity | O2: High Value Flag
B3: 1 | C3: P001 | D3: Book Shelves | E3: Furniture | F3: 36 | G3: 36 | H3: 3000 | I3: =Table13[[#This Row],[Physical_Stock_Qty]]-Table13[[#This Row],[System_Stock_Qty]] -> 0 | J3: {=_xlfn.IFS(I3=0,"Matched",I3>0,"Excess",I3<0,"Shortage")} -> Matched | K3: =ABS(Table13[[#This Row],[Stock Difference]]) -> 0 | L3: =(K3*H3) -> 0 | M3: =F3*H3 -> 108000 | N3: {=_xlfn.IFS(K3=0,"Matched", K3>100,"High", K3>=50,"Medium", K3<50,"Low")} -> Matched | O3: =IF(L3>500000,"Yes",IF(L3=0,"No Match","No")) -> No Match
B4: 2 | C4: P002 | D4: Car Play | E4: Electronics | F4: 192 | G4: 192 | H4: 15000 | I4: =Table13[[#This Row],[Physical_Stock_Qty]]-Table13[[#This Row],[System_Stock_Qty]] -> 0 | J4: {=_xlfn.IFS(I4=0,"Matched",I4>0,"Excess",I4<0,"Shortage")} -> Matched | K4: =ABS(Table13[[#This Row],[Stock Difference]]) -> 0 | L4: =(K4*H4) -> 0 | M4: =F4*H4 -> 2880000 | N4: {=_xlfn.IFS(K4=0,"Matched", K4>100,"High", K4>=50,"Medium", K4<50,"Low")} -> Matched | O4: =IF(L4>500000,"Yes",IF(L4=0,"No Match","No")) -> No Match
B5: 3 | C5: P003 | D5: Pen Drive | E5: Accessories | F5: 191 | G5: 191 | H5: 200 | I5: =Table13[[#This Row],[Physical_Stock_Qty]]-Table13[[#This Row],[System_Stock_Qty]] -> 0 | J5: {=_xlfn.IFS(I5=0,"Matched",I5>0,"Excess",I5<0,"Shortage")} -> Matched | K5: =ABS(Table13[[#This Row],[Stock Difference]]) -> 0 | L5: =(K5*H5) -> 0 | M5: =F5*H5 -> 38200 | N5: {=_xlfn.IFS(K5=0,"Matched", K5>100,"High", K5>=50,"Medium", K5<50,"Low")} -> Matched | O5: =IF(L5>500000,"Yes",IF(L5=0,"No Match","No")) -> No Match
B6: 4 | C6: P004 | D6: Books | E6: Stationery | F6: 91 | G6: 91 | H6: 50 | I6: =Table13[[#This Row],[Physical_Stock_Qty]]-Table13[[#This Row],[System_Stock_Qty]] -> 0 | J6: {=_xlfn.IFS(I6=0,"Matched",I6>0,"Excess",I6<0,"Shortage")} -> Matched | K6: =ABS(Table13[[#This Row],[Stock Difference]]) -> 0 | L6: =(K6*H6) -> 0 | M6: =F6*H6 -> 4550 | N6: {=_xlfn.IFS(K6=0,"Matched", K6>100,"High", K6>=50,"Medium", K6<50,"Low")} -> Matched | O6: =IF(L6>500000,"Yes",IF(L6=0,"No Match","No")) -> No Match
B7: 5 | C7: P005 | D7: Rack Mount Kit | E7: Networking | F7: 62 | G7: 62 | H7: 5000 | I7: =Table13[[#This Row],[Physical_Stock_Qty]]-Table13[[#This Row],[System_Stock_Qty]] -> 0 | J7: {=_xlfn.IFS(I7=0,"Matched",I7>0,"Excess",I7<0,"Shortage")} -> Matched | K7: =ABS(Table13[[#This Row],[Stock Difference]]) -> 0 | L7: =(K7*H7) -> 0 | M7: =F7*H7 -> 310000 | N7: {=_xlfn.IFS(K7=0,"Matched", K7>100,"High", K7>=50,"Medium", K7<50,"Low")} -> Matched | O7: =IF(L7>500000,"Yes",IF(L7=0,"No Match","No")) -> No Match
B8: 6 | C8: P006 | D8: Cardboard | E8: Stationery | F8: 98 | G8: 98 | H8: 50 | I8: =Table13[[#This Row],[Physical_Stock_Qty]]-Table13[[#This Row],[System_Stock_Qty]] -> 0 | J8: {=_xlfn.IFS(I8=0,"Matched",I8>0,"Excess",I8<0,"Shortage")} -> Matched | K8: =ABS(Table13[[#This Row],[Stock Difference]]) -> 0 | L8: =(K8*H8) -> 0 | M8: =F8*H8 -> 4900 | N8: {=_xlfn.IFS(K8=0,"Matched", K8>100,"High", K8>=50,"Medium", K8<50,"Low")} -> Matched | O8: =IF(L8>500000,"Yes",IF(L8=0,"No Match","No")) -> No Match
B9: 7 | C9: P007 | D9: Network Interface Card (NIC) | E9: Networking | F9: 184 | G9: 184 | H9: 2000 | I9: =Table13[[#This Row],[Physical_Stock_Qty]]-Table13[[#This Row],[System_Stock_Qty]] -> 0 | J9: {=_xlfn.IFS(I9=0,"Matched",I9>0,"Excess",I9<0,"Shortage")} -> Matched | K9: =ABS(Table13[[#This Row],[Stock Difference]]) -> 0 | L9: =(K9*H9) -> 0 | M9: =F9*H9 -> 368000 | N9: {=_xlfn.IFS(K9=0,"Matched", K9>100,"High", K9>=50,"Medium", K9<50,"Low")} -> Matched | O9: =IF(L9>500000,"Yes",IF(L9=0,"No Match","No")) -> No Match
B10: 8 | C10: P008 | D10: table | E10: Furniture | F10: 79 | G10: 79 | H10: 8000 | I10: =Table13[[#This Row],[Physical_Stock_Qty]]-Table13[[#This Row],[System_Stock_Qty]] -> 0 | J10: {=_xlfn.IFS(I10=0,"Matched",I10>0,"Excess",I10<0,"Shortage")} -> Matched | K10: =ABS(Table13[[#This Row],[Stock Difference]]) -> 0 | L10: =(K10*H10) -> 0 | M10: =F10*H10 -> 632000 | N10: {=_xlfn.IFS(K10=0,"Matched", K10>100,"High", K10>=50,"Medium", K10<50,"Low")} -> Matched | O10: =IF(L10>500000,"Yes",IF(L10=0,"No Match","No")) -> No Match
B11: 9 | C11: P009 | D11: Network Cable (Ethernet) | E11: Networking | F11: 68 | G11: 68 | H11: 5000 | I11: =Table13[[#This Row],[Physical_Stock_Qty]]-Table13[[#This Row],[System_Stock_Qty]] -> 0 | J11: {=_xlfn.IFS(I11=0,"Matched",I11>0,"Excess",I11<0,"Shortage")} -> Matched | K11: =ABS(Table13[[#This Row],[Stock Difference]]) -> 0 | L11: =(K11*H11) -> 0 | M11: =F11*H11 -> 340000 | N11: {=_xlfn.IFS(K11=0,"Matched", K11>100,"High", K11>=50,"Medium", K11<50,"Low")} -> Matched | O11: =IF(L11>500000,"Yes",IF(L11=0,"No Match","No")) -> No Match
B12: 10 | C12: P010 | D12: Apple Watch | E12: Electronics | F12: 161 | G12: 161 | H12: 30000 | I12: =Table13[[#This Row],[Physical_Stock_Qty]]-Table13[[#This Row],[System_Stock_Qty]] -> 0 | J12: {=_xlfn.IFS(I12=0,"Matched",I12>0,"Excess",I12<0,"Shortage")} -> Matched | K12: =ABS(Table13[[#This Row],[Stock Difference]]) -> 0 | L12: =(K12*H12) -> 0 | M12: =F12*H12 -> 4830000 | N12: {=_xlfn.IFS(K12=0,"Matched", K12>100,"High", K12>=50,"Medium", K12<50,"Low")} -> Matched | O12: =IF(L12>500000,"Yes",IF(L12=0,"No Match","No")) -> No Match
B13: 11 | C13: P011 | D13: Pilers | E13: Hardware | F13: 34 | G13: 34 | H13: 500 | I13: =Table13[[#This Row],[Physical_Stock_Qty]]-Table13[[#This Row],[System_Stock_Qty]] -> 0 | J13: {=_xlfn.IFS(I13=0,"Matched",I13>0,"Excess",I13<0,"Shortage")} -> Matched | K13: =ABS(Table13[[#This Row],[Stock Difference]]) -> 0 | L13: =(K13*H13) -> 0 | M13: =F13*H13 -> 17000 | N13: {=_xlfn.IFS(K13=0,"Matched", K13>100,"High", K13>=50,"Medium", K13<50,"Low")} -> Matched | O13: =IF(L13>500000,"Yes",IF(L13=0,"No Match","No")) -> No Match
B14: 12 | C14: P012 | D14: Drill Machine | E14: Hardware | F14: 43 | G14: 43 | H14: 3000 | I14: =Table13[[#This Row],[Physical_Stock_Qty]]-Table13[[#This Row],[System_Stock_Qty]] -> 0 | J14: {=_xlfn.IFS(I14=0,"Matched",I14>0,"Excess",I14<0,"Shortage")} -> Matched | K14: =ABS(Table13[[#This Row],[Stock Difference]]) -> 0 | L14: =(K14*H14) -> 0 | M14: =F14*H14 -> 129000 | N14: {=_xlfn.IFS(K14=0,"Matched", K14>100,"High", K14>=50,"Medium", K14<50,"Low")} -> Matched | O14: =IF(L14>500000,"Yes",IF(L14=0,"No Match","No")) -> No Match
... B1003: 1001 | C1003: P1001 | D1003: Colors | E1003: Stationery | F1003: 20 | G1003: 20 | H1003: 50 | I1003: =Table13[[#This Row],[Physical_Stock_Qty]]-Table13[[#This Row],[System_Stock_Qty]] -> 0 | J1003: {=_xlfn.IFS(I1003=0,"Matched",I1003>0,"Excess",I1003<0,"Shortage")} -> Matched | K1003: =ABS(Table13[[#This Row],[Stock Difference]]) -> 0 | L1003: =(K1003*H1003) -> 0 | M1003: =F1003*H1003 -> 1000 | N1003: {=_xlfn.IFS(K1003=0,"Matched", K1003>100,"High", K1003>=50,"Medium", K1003<50,"Low")} -> Matched | O1003: =IF(L1003>500000,"Yes",IF(L1003=0,"No Match","No")) -> No Match

Sheet analysis
B2: STOCK MISMATCH ANALYSIS
B3: Total Product | D3: =COUNT(Table13[Sr. No. ]) -> 1001 | E3: Formula Used:- COUNT(Table13[Sr. No. ])
B4: Mismatch | D4: =D5+D6 -> 298 | E4: Formula Used:- SUM(shortage:excess)-Mismatch
B5: Shortage | D5: =COUNTIF('main sheet'!J:J,analysis!B5) -> 152 | E5: Formula Used:- COUNTIF('main sheet'!J:J,analysis!B5)
B6: Excess | D6: =COUNTIF('main sheet'!J:J,analysis!B6) -> 146 | E6: Formula Used:- COUNTIF('main sheet'!J:J,analysis!B6)
B7: Inventory Accuracy % | D7: =COUNTIF('main sheet'!J:J,'raw sheet'!J22)/analysis!D3 -> 0.7022977 | E7: Formula Used:- Matched product / Total Product
B8: Total Financial Impact | D8: =SUM(Table13[Total Product Value]) -> 882187210 | E8: Formula Used:- SUM(Table13[Total Product Value]) Formating :-#,##0,,\M
B9: Top 10 shortages | C9: Product | D9: Count. Of Prodcuts | E9: Formula Used:- Pivot table
C10: Dressing table | D10: 8
C11: Measuring Tape | D11: 7
C12: Chairs | D12: 6
C13: Chain Saw Blade | D13: 6
C14: Firewall Appliance | D14: 6
C15: Phone Mount | D15: 5
C16: Compas | D16: 5
C17: Wrench | D17: 5
C18: Apple Watch | D18: 5
C19: Drill Machine | D19: 5
B20: Top 10 Excess | C20: Product | D20: Count. Of Prodcuts | E20: Formula Used:- Pivot table
C21: Wrench | D21: 8
C22: Drill Machine | D22: 7
C23: Pens | D23: 6
C24: Book Shelves | D24: 6
C25: Study Table | D25: 6
C26: Dressing table | D26: 6
C27: Firewall Appliance | D27: 6
C28: Doors | D28: 5
C29: Books | D29: 5
C30: Chain Saw Blade | D30: 5
B31: Category-wise Accuracy | C31: Category | D31: Accuracy %
C32: Electronics | D32: =COUNTIF('main sheet'!E:E,analysis!C32)/analysis!$D$3 -> 0.16783217 | E32: Formula Used:- =COUNTIF('main sheet'!E:E,analysis!C32)/analysis!$D$3
C33: Furniture | D33: =COUNTIF('main sheet'!E:E,analysis!C33)/analysis!$D$3 -> 0.16683317 | E33: Formula Used:- =COUNTIF('main sheet'!E:E,analysis!C33)/analysis!$D$4
C34: Stationery | D34: =COUNTIF('main sheet'!E:E,analysis!C34)/analysis!$D$3 -> 0.18281718 | E34: Formula Used:- =COUNTIF('main sheet'!E:E,analysis!C34)/analysis!$D$5
C35: Hardware | D35: =COUNTIF('main sheet'!E:E,analysis!C35)/analysis!$D$3 -> 0.16783217 | E35: Formula Used:- =COUNTIF('main sheet'!E:E,analysis!C35)/analysis!$D$6
C36: Accessories | D36: =COUNTIF('main sheet'!E:E,analysis!C36)/analysis!$D$3 -> 0.16383616 | E36: Formula Used:- =COUNTIF('main sheet'!E:E,analysis!C36)/analysis!$D$7
C37: Networking | D37: =COUNTIF('main sheet'!E:E,analysis!C37)/analysis!$D$3 -> 0.15084915 | E37: Formula Used:- =COUNTIF('main sheet'!E:E,analysis!C37)/analysis!$D$8
B38: Category-wise Financial Loss | C38: Category | D38: Financial Impact | E38: Formula Used:- Pivot table
C39: Electronics | D39: 93498000
C40: Furniture | D40: 35028000
C41: Networking | D41: 10205800
...

Sheet pivot tables
B2: Status Summery | E2: Category wise financial Losses | H2: Status | I2: (All) | Q2: Status | R2: Shortage
B3: Row Labels | C3: Count of Sr. No. | E3: Row Labels | F3: Sum of Value Impact | H3: Category Wise Accuracy | K3: Severity Analysis | N3: Top Costly Mismatch | Q3: Shortage Analysis | T3: Status | U3: Excess
B4: Matched | C4: 702 | E4: Electronics | F4: 84532000 | H4: Row Labels | I4: Count of Product ID | K4: Row Labels | L4: Count of Product ID | N4: Row Labels | O4: Sum of Value Impact | Q4: Row Labels | R4: Sum of Mismatch Qty | T4: Excess Analysis
B5: Shortage | C5: 152 | E5: Furniture | F5: 26504000 | H5: Accessories | I5: 164 | K5: High | L5: 51 | N5: Iphone | O5: 30750000 | Q5: Dressing table | R5: 432 | T5: Row Labels | U5: Sum of Mismatch Qty
B6: Excess | C6: 146 | E6: Networking | F6: 7789600 | H6: Electronics | I6: 168 | K6: Low | L6: 138 | N6: Cameras | O6: 14280000 | Q6: Drill Machine | R6: 357 | T6: Bed | U6: 414
B7: Grand Total | C7: 1000 | E7: Accessories | F7: 3912400 | H7: Furniture | I7: 167 | K7: Medium | L7: 109 | N7: Bed | O7: 11475000 | Q7: Bed | R7: 351 | T7: Pens | U7: 407
E8: Hardware | F8: 2878100 | H8: Hardware | I8: 168 | K8: Grand Total | L8: 298 | N8: AC set | O8: 8950000 | Q8: Dryer | R8: 346 | T8: Compas | U8: 339
E9: Stationery | F9: 233880 | H9: Networking | I9: 151 | N9: Apple Watch | O9: 7680000 | Q9: Modem | R9: 322 | T9: Study Table | U9: 310
E10: Grand Total | F10: 125849980 | H10: Stationery | I10: 182 | N10: Tabs | O10: 7380000 | Q10: Cable Tester | R10: 316 | T10: AccessPoint (Wi-Fi AP) | U10: 280
H11: Grand Total | I11: 1000 | N11: Dressing table | O11: 5610000 | Q11: Chain Saw Blade | R11: 311 | T11: Headphone | U11: 278
N12: washing maching | O12: 4600000 | Q12: Pilers | R12: 300 | T12: Wrench | U12: 273
N13: Car Play | O13: 4500000 | Q13: Headphone | R13: 261 | T13: Books | U13: 230
N14: Dinning table | O14: 2772000 | Q14: Wrench | R14: 255 | T14: Wireless Charger | U14: 228
N15: Grand Total | O15: 97997000 | Q15: Grand Total | R15: 3251 | T15: Pen Drive | U15: 212
T16: Grand Total | U16: 2971
